#VRML_SIM R2025a utf8

EXTERNPROTO "https://raw.githubusercontent.com/cyberbotics/webots/R2025a/projects/objects/backgrounds/protos/TexturedBackground.proto"
EXTERNPROTO "https://raw.githubusercontent.com/cyberbotics/webots/R2025a/projects/objects/backgrounds/protos/TexturedBackgroundLight.proto"
EXTERNPROTO "https://raw.githubusercontent.com/cyberbotics/webots/R2025a/projects/objects/floors/protos/RectangleArena.proto"
EXTERNPROTO "https://raw.githubusercontent.com/cyberbotics/webots/R2025a/projects/robots/gctronic/e-puck/protos/E-puck.proto"

WorldInfo {
  contactProperties [
    ContactProperties {
      material1 "caster_material"
      coulombFriction [
        0
      ]
    }
  ]
}
Viewpoint {
  orientation -0.044802124567121654 -0.05560263673955276 0.9974473000724807 2.65
  position 1.84 -1.24 0.44
}
TexturedBackground {
}
TexturedBackgroundLight {
}
RectangleArena {
  floorSize 10 10
}
Robot {
  translation 0.5 0.1 0.024607092210555234
  rotation -0.9558335550535082 -0.2811275161922072 0.08572942711445375 1.7127359199056658e-16
  children [
    Shape {
      appearance PBRAppearance {
        baseColor 0.8 0.1 0.1
        roughness 1
      }
      geometry Box {
        size 0.2 0.1 0.05
      }
    }
  ]
  name "SimpleRobot"
  boundingObject Box {
    size 0.2 0.1 0.05
  }
  physics Physics {
  }
  controller "simple_controller"
  linearVelocity -1.9275523163041974e-17 1.832739751193371e-17 3.97683793448089e-06
  angularVelocity -8.526512829121202e-16 -5.015595781835997e-16 9.822206442236393e-17
}
E-puck {
  hidden position_0_0 12.617605752570189
  hidden position_0_1 12.617605751962214
  hidden linearVelocity_0 0.00016326007564523295 -4.855160911867344e-11 -1.961370780154214e-08
  hidden angularVelocity_0 3.236736774696822e-09 0.010883994295126714 -5.198548653833864e-11
  hidden rotation_1 0 0.9999999999999999 0 0.05123513821101903
  hidden linearVelocity_1 0.0002176797285290274 -6.473765467077494e-11 -2.3202373387571083e-11
  hidden angularVelocity_1 3.2369900480361277e-09 0.010883994288578929 5.0640215565351033e-11
  hidden rotation_2 0 1 0 0.05123513760304557
  hidden linearVelocity_2 0.00021767972685771624 -6.473152027035861e-11 -2.312492419314215e-11
  hidden angularVelocity_2 3.2360741646243105e-09 0.010883994288512208 -1.5461181971134988e-10
  translation 4.053209483182979 1.9000001123692414 -6.396278559704822e-05
  rotation 2.5717443896769065e-05 -0.9999950262871308 -0.003153845210832036 9.433056482510798e-05
  controller "simple_controller"
}
Robot {
  translation 0 -0.7 0.041
  children [
    Shape {
      appearance PBRAppearance {
        baseColor 0.95 0.95 0.95
        roughness 0.8
        metalness 0
      }
      geometry Cylinder {
        height 0.08
        radius 0.06
      }
    }
    HingeJoint {
      jointParameters HingeJointParameters {
        axis 0 0 1
        minStop -1.57
        maxStop 1.57
      }
      device [
        RotationalMotor {
          name "base_joint"
          maxVelocity 2
          maxTorque 5
        }
      ]
      endPoint Solid {
        translation 0 0 0.04
        children [
          Shape {
            appearance PBRAppearance {
              baseColor 1 0.4 0.05
              roughness 0.8
              metalness 0
            }
            geometry Cylinder {
              height 0.03
              radius 0.05
            }
          }
          HingeJoint {
            jointParameters HingeJointParameters {
              axis 0 1 0
              anchor 0 0 0.02
              minStop -1.3
              maxStop 1.3
            }
            device [
              RotationalMotor {
                name "shoulder_joint"
                maxVelocity 2
                maxTorque 5
              }
            ]
            endPoint Solid {
              translation 0 0 0.02
              children [
                Pose {
                  translation 0 0 0.06
                  children [
                    Shape {
                      appearance PBRAppearance {
                        baseColor 1 0.4 0.05
                        roughness 0.8
                        metalness 0
                      }
                      geometry Box {
                        size 0.04 0.04 0.12
                      }
                    }
                  ]
                }
                Pose {
                  children [
                    Shape {
                      appearance PBRAppearance {
                        baseColor 0.15 0.15 0.15
                        roughness 0.6
                        metalness 0.1
                      }
                      geometry Box {
                        size 0.042 0.042 0.03
                      }
                    }
                  ]
                }
                HingeJoint {
                  jointParameters HingeJointParameters {
                    axis 0 1 0
                    anchor 0 0 0.12
                    minStop -1.57
                    maxStop 1.57
                  }
                  device [
                    RotationalMotor {
                      name "elbow_joint"
                      maxVelocity 2
                      maxTorque 4
                    }
                  ]
                  endPoint Solid {
                    translation 0 0 0.12
                    children [
                      Pose {
                        translation 0 0 0.06
                        children [
                          Shape {
                            appearance PBRAppearance {
                              baseColor 1 0.4 0.05
                              roughness 0.8
                              metalness 0
                            }
                            geometry Box {
                              size 0.035 0.035 0.12
                            }
                          }
                        ]
                      }
                      Pose {
                        children [
                          Shape {
                            appearance PBRAppearance {
                              baseColor 0.15 0.15 0.15
                              roughness 0.6
                              metalness 0.1
                            }
                            geometry Box {
                              size 0.038 0.038 0.03
                            }
                          }
                        ]
                      }
                      HingeJoint {
                        jointParameters HingeJointParameters {
                          axis 0 1 0
                          anchor 0 0 0.12
                          minStop -1.57
                          maxStop 1.57
                        }
                        device [
                          RotationalMotor {
                            name "wrist_pitch_joint"
                            maxVelocity 3
                            maxTorque 3
                          }
                        ]
                        endPoint Solid {
                          translation 0 0 0.12
                          children [
                            Pose {
                              translation 0 0 0.02
                              children [
                                Shape {
                                  appearance PBRAppearance {
                                    baseColor 1 0.4 0.05
                                    roughness 0.8
                                    metalness 0
                                  }
                                  geometry Box {
                                    size 0.03 0.03 0.04
                                  }
                                }
                              ]
                            }
                            HingeJoint {
                              jointParameters HingeJointParameters {
                                axis 0 0 1
                                anchor 0 0 0.04
                                minStop -3.14
                                maxStop 3.14
                              }
                              device [
                                RotationalMotor {
                                  name "wrist_roll_joint"
                                  maxVelocity 4
                                  maxTorque 2
                                }
                              ]
                              endPoint Solid {
                                translation 0 0 0.04
                                children [
                                  Shape {
                                    appearance PBRAppearance {
                                      baseColor 0.95 0.95 0.95
                                      roughness 0.8
                                      metalness 0
                                    }
                                    geometry Box {
                                      size 0.04 0.05 0.02
                                    }
                                  }
                                  HingeJoint {
                                    jointParameters HingeJointParameters {
                                      axis 0 1 0
                                      anchor 0 0 0.01
                                      minStop 0
                                      maxStop 0.8
                                    }
                                    device [
                                      RotationalMotor {
                                        name "gripper_joint"
                                        maxVelocity 3
                                        maxTorque 2
                                      }
                                    ]
                                    endPoint Solid {
                                      translation 0 0 0.01
                                      children [
                                        Pose {
                                          translation 0 0.012 0.02
                                          children [
                                            Shape {
                                              appearance PBRAppearance {
                                                baseColor 0.95 0.95 0.95
                                                roughness 0.8
                                                metalness 0
                                              }
                                              geometry Box {
                                                size 0.008 0.003 0.04
                                              }
                                            }
                                          ]
                                        }
                                        Pose {
                                          translation 0 -0.012 0.02
                                          children [
                                            Shape {
                                              appearance PBRAppearance {
                                                baseColor 0.95 0.95 0.95
                                                roughness 0.8
                                                metalness 0
                                              }
                                              geometry Box {
                                                size 0.008 0.003 0.04
                                              }
                                            }
                                          ]
                                        }
                                        Shape {
                                          appearance PBRAppearance {
                                            baseColor 0.95 0.95 0.95
                                            roughness 0.8
                                            metalness 0
                                          }
                                          geometry Box {
                                            size 0.035 0.03 0.01
                                          }
                                        }
                                      ]
                                      name "gripper_finger"
                                      boundingObject Pose {
                                        translation 0 0 0.02
                                        children [
                                          Box {
                                            size 0.06 0.015 0.04
                                          }
                                        ]
                                      }
                                      physics Physics {
                                      }
                                    }
                                  }
                                ]
                                name "wrist_roll_link"
                                boundingObject Box {
                                  size 0.04 0.05 0.02
                                }
                                physics Physics {
                                }
                              }
                            }
                          ]
                          name "wrist_pitch_link"
                          boundingObject Pose {
                            translation 0 0 0.02
                            children [
                              Box {
                                size 0.03 0.03 0.04
                              }
                            ]
                          }
                          physics Physics {
                          }
                        }
                      }
                    ]
                    name "elbow_link"
                    boundingObject Pose {
                      translation 0 0 0.06
                      children [
                        Box {
                          size 0.035 0.035 0.12
                        }
                      ]
                    }
                    physics Physics {
                    }
                  }
                }
              ]
              name "shoulder_link"
              boundingObject Pose {
                translation 0 0 0.06
                children [
                  Box {
                    size 0.04 0.04 0.12
                  }
                ]
              }
              physics Physics {
              }
            }
          }
        ]
        name "base_link"
        boundingObject Cylinder {
          height 0.03
          radius 0.05
        }
        physics Physics {
        }
      }
    }
  ]
  name "ServoArm"
  boundingObject Cylinder {
    height 0.08
    radius 0.06
  }
  controller "arm_http_controller"
}
